[34m[1mwandb[0m: [32m[41mERROR[0m artifact 'segment_dataset_reference:v0' not found in 'poornima-dharamdasani-danfoss/segment'
Traceback (most recent call last):
  File "/home/danfossautonomypc/.local/lib/python3.10/site-packages/wandb/apis/normalize.py", line 25, in wrapper
    return func(*args, **kwargs)
  File "/home/danfossautonomypc/.local/lib/python3.10/site-packages/wandb/apis/public/api.py", line 1210, in _artifact
    artifact = wandb.Artifact._from_name(
  File "/home/danfossautonomypc/.local/lib/python3.10/site-packages/wandb/sdk/artifacts/artifact.py", line 279, in _from_name
    raise ValueError(f"artifact '{name}' not found in '{entity}/{project}'")
ValueError: artifact 'segment_dataset_reference:v0' not found in 'poornima-dharamdasani-danfoss/segment'

During handling of the above exception, another exception occurred:

Traceback (most recent call last):
  File "/home/danfossautonomypc/segmentation/wandb_segment/increment_refdata_use.py", line 13, in <module>
    artifact = run.use_artifact('poornima-dharamdasani-danfoss/segment/segment_dataset_reference:v0', type='dataset')
  File "/home/danfossautonomypc/.local/lib/python3.10/site-packages/wandb/sdk/wandb_run.py", line 403, in wrapper_fn
    return func(self, *args, **kwargs)
  File "/home/danfossautonomypc/.local/lib/python3.10/site-packages/wandb/sdk/wandb_run.py", line 393, in wrapper
    return func(self, *args, **kwargs)
  File "/home/danfossautonomypc/.local/lib/python3.10/site-packages/wandb/sdk/wandb_run.py", line 3071, in use_artifact
    artifact = public_api._artifact(type=type, name=name)
  File "/home/danfossautonomypc/.local/lib/python3.10/site-packages/wandb/apis/normalize.py", line 71, in wrapper
    raise CommError(message, err).with_traceback(sys.exc_info()[2])
  File "/home/danfossautonomypc/.local/lib/python3.10/site-packages/wandb/apis/normalize.py", line 25, in wrapper
    return func(*args, **kwargs)
  File "/home/danfossautonomypc/.local/lib/python3.10/site-packages/wandb/apis/public/api.py", line 1210, in _artifact
    artifact = wandb.Artifact._from_name(
  File "/home/danfossautonomypc/.local/lib/python3.10/site-packages/wandb/sdk/artifacts/artifact.py", line 279, in _from_name
    raise ValueError(f"artifact '{name}' not found in '{entity}/{project}'")
wandb.errors.errors.CommError: artifact 'segment_dataset_reference:v0' not found in 'poornima-dharamdasani-danfoss/segment'
Traceback (most recent call last):
  File "/home/danfossautonomypc/.local/lib/python3.10/site-packages/wandb/apis/normalize.py", line 25, in wrapper
    return func(*args, **kwargs)
  File "/home/danfossautonomypc/.local/lib/python3.10/site-packages/wandb/apis/public/api.py", line 1210, in _artifact
    artifact = wandb.Artifact._from_name(
  File "/home/danfossautonomypc/.local/lib/python3.10/site-packages/wandb/sdk/artifacts/artifact.py", line 279, in _from_name
    raise ValueError(f"artifact '{name}' not found in '{entity}/{project}'")
ValueError: artifact 'segment_dataset_reference:v0' not found in 'poornima-dharamdasani-danfoss/segment'

During handling of the above exception, another exception occurred:

Traceback (most recent call last):
  File "/home/danfossautonomypc/segmentation/wandb_segment/increment_refdata_use.py", line 13, in <module>
    artifact = run.use_artifact('poornima-dharamdasani-danfoss/segment/segment_dataset_reference:v0', type='dataset')
  File "/home/danfossautonomypc/.local/lib/python3.10/site-packages/wandb/sdk/wandb_run.py", line 403, in wrapper_fn
    return func(self, *args, **kwargs)
  File "/home/danfossautonomypc/.local/lib/python3.10/site-packages/wandb/sdk/wandb_run.py", line 393, in wrapper
    return func(self, *args, **kwargs)
  File "/home/danfossautonomypc/.local/lib/python3.10/site-packages/wandb/sdk/wandb_run.py", line 3071, in use_artifact
    artifact = public_api._artifact(type=type, name=name)
  File "/home/danfossautonomypc/.local/lib/python3.10/site-packages/wandb/apis/normalize.py", line 71, in wrapper
    raise CommError(message, err).with_traceback(sys.exc_info()[2])
  File "/home/danfossautonomypc/.local/lib/python3.10/site-packages/wandb/apis/normalize.py", line 25, in wrapper
    return func(*args, **kwargs)
  File "/home/danfossautonomypc/.local/lib/python3.10/site-packages/wandb/apis/public/api.py", line 1210, in _artifact
    artifact = wandb.Artifact._from_name(
  File "/home/danfossautonomypc/.local/lib/python3.10/site-packages/wandb/sdk/artifacts/artifact.py", line 279, in _from_name
    raise ValueError(f"artifact '{name}' not found in '{entity}/{project}'")
wandb.errors.errors.CommError: artifact 'segment_dataset_reference:v0' not found in 'poornima-dharamdasani-danfoss/segment'
